<?xml version="1.0" encoding="utf-8"?>
<robot name="slam_bot">
  <link name="base_link">
    <inertial>
      <origin
        xyz="0.63263 0.85695 1.329"
        rpy="0 0 0" />
      <mass
        value="1.2391" />
      <inertia
        ixx="0.0041453"
        ixy="-2.6591E-06"
        ixz="9.0036E-06"
        iyy="0.0062191"
        iyz="4.9674E-05"
        izz="0.0027737" />
    </inertial>
    <visual>
      <origin
        xyz="0 0 0"
        rpy="0 0 0" />
      <geometry>
        <mesh
          filename="package://virtual_lab/meshes/base_link.STL" />
      </geometry>
      <material
        name="">
        <color
          rgba="0.79216 0.81961 0.93333 1" />
      </material>
    </visual>
    <collision>
      <origin
        xyz="0 0 0"
        rpy="0 0 0" />
      <geometry>
        <mesh
          filename="package://virtual_lab/meshes/base_link.STL" />
      </geometry>
    </collision>
  </link>
  <link
    name="fr_left_wheel_link">
    <inertial>
      <origin
        xyz="-4.5465E-09 -2.2877E-10 -0.011873"
        rpy="0 0 0" />
      <mass
        value="0.021403" />
      <inertia
        ixx="8.6276E-06"
        ixy="1.8968E-13"
        ixz="-7.5832E-17"
        iyy="8.6271E-06"
        iyz="1.5767E-14"
        izz="1.4513E-05" />
    </inertial>
    <visual>
      <origin
        xyz="0 0 0"
        rpy="0 0 0" />
      <geometry>
        <mesh
          filename="package://virtual_lab/meshes/fr_left_wheel_link.STL" />
      </geometry>
      <material
        name="">
        <color
          rgba="0.29804 0.29804 0.29804 1" />
      </material>
    </visual>
    <collision>
      <origin
        xyz="0 0 0"
        rpy="0 0 0" />
      <geometry>
        <mesh
          filename="package://virtual_lab/meshes/fr_left_wheel_link.STL" />
      </geometry>
    </collision>
  </link>
  <joint
    name="fr_left_wheel_joint"
    type="continuous">
    <origin
      xyz="0.73816 -1.3964 0.82211"
      rpy="-1.5708 1.379 -1.5708" />
    <parent
      link="base_link" />
    <child
      link="fr_left_wheel_link" />
    <axis
      xyz="0 1 0" />
  </joint>
  <link
    name="fr_right_wheel_link">
    <inertial>
      <origin
        xyz="-4.4841E-09 -1.7372E-10 -0.011873"
        rpy="0 0 0" />
      <mass
        value="0.021403" />
      <inertia
        ixx="8.6276E-06"
        ixy="1.9135E-13"
        ixz="-7.3012E-15"
        iyy="8.6271E-06"
        iyz="1.4288E-14"
        izz="1.4513E-05" />
    </inertial>
    <visual>
      <origin
        xyz="0 0 0"
        rpy="0 0 0" />
      <geometry>
        <mesh
          filename="package://virtual_lab/meshes/fr_right_wheel_link.STL" />
      </geometry>
      <material
        name="">
        <color
          rgba="0.29804 0.29804 0.29804 1" />
      </material>
    </visual>
    <collision>
      <origin
        xyz="0 0 0"
        rpy="0 0 0" />
      <geometry>
        <mesh
          filename="package://virtual_lab/meshes/fr_right_wheel_link.STL" />
      </geometry>
    </collision>
  </link>
  <joint
    name="fr_right_wheel_joint"
    type="continuous">
    <origin
      xyz="0.52756 -1.3964 0.82211"
      rpy="1.5708 1.379 -1.5708" />
    <parent
      link="base_link" />
    <child
      link="fr_right_wheel_link" />
    <axis
      xyz="0 1 0" />
  </joint>
  <link
    name="bk_left_wheel_link">
    <inertial>
      <origin
        xyz="-4.4841E-09 -1.7372E-10 -0.011873"
        rpy="0 0 0" />
      <mass
        value="0.021403" />
      <inertia
        ixx="8.6276E-06"
        ixy="1.9134E-13"
        ixz="-7.3014E-15"
        iyy="8.6271E-06"
        iyz="1.4288E-14"
        izz="1.4513E-05" />
    </inertial>
    <visual>
      <origin
        xyz="0 0 0"
        rpy="0 0 0" />
      <geometry>
        <mesh
          filename="package://virtual_lab/meshes/bk_left_wheel_link.STL" />
      </geometry>
      <material
        name="">
        <color
          rgba="0.29804 0.29804 0.29804 1" />
      </material>
    </visual>
    <collision>
      <origin
        xyz="0 0 0"
        rpy="0 0 0" />
      <geometry>
        <mesh
          filename="package://virtual_lab/meshes/bk_left_wheel_link.STL" />
      </geometry>
    </collision>
  </link>
  <joint
    name="bk_left_wheel_joint"
    type="continuous">
    <origin
      xyz="0.73816 -1.2653 0.82211"
      rpy="1.5708 1.379 1.5708" />
    <parent
      link="base_link" />
    <child
      link="bk_left_wheel_link" />
    <axis
      xyz="0 1 0" />
  </joint>
  <link
    name="bk_right_wheel_link">
    <inertial>
      <origin
        xyz="-4.5465E-09 -2.2877E-10 -0.011873"
        rpy="0 0 0" />
      <mass
        value="0.021403" />
      <inertia
        ixx="8.6276E-06"
        ixy="1.8968E-13"
        ixz="-7.5287E-17"
        iyy="8.6271E-06"
        iyz="1.5767E-14"
        izz="1.4513E-05" />
    </inertial>
    <visual>
      <origin
        xyz="0 0 0"
        rpy="0 0 0" />
      <geometry>
        <mesh
          filename="package://virtual_lab/meshes/bk_right_wheel_link.STL" />
      </geometry>
      <material
        name="">
        <color
          rgba="0.29804 0.29804 0.29804 1" />
      </material>
    </visual>
    <collision>
      <origin
        xyz="0 0 0"
        rpy="0 0 0" />
      <geometry>
        <mesh
          filename="package://virtual_lab/meshes/bk_right_wheel_link.STL" />
      </geometry>
    </collision>
  </link>
  <joint
    name="bk_right_wheel_joint"
    type="continuous">
    <origin
      xyz="0.52756 -1.2653 0.82211"
      rpy="-1.5708 1.379 1.5708" />
    <parent
      link="base_link" />
    <child
      link="bk_right_wheel_link" />
    <axis
      xyz="0 1 0" />
  </joint>
  <link
    name="lidar_link">
    <inertial>
      <origin
        xyz="4.4433E-08 0.018462 -7.7482E-05"
        rpy="0 0 0" />
      <mass
        value="0.74835" />
      <inertia
        ixx="0.00025778"
        ixy="9.5139E-11"
        ixz="-6.2173E-10"
        iyy="0.00031753"
        iyz="-7.6812E-07"
        izz="0.00025587" />
    </inertial>
    <visual>
      <origin
        xyz="0 0 0"
        rpy="0 0 0" />
      <geometry>
        <mesh
          filename="package://virtual_lab/meshes/lidar_link.STL" />
      </geometry>
      <material
        name="">
        <color
          rgba="0.77647 0.75686 0.73725 1" />
      </material>
    </visual>
    <collision>
      <origin
        xyz="0 0 0"
        rpy="0 0 0" />
      <geometry>
        <mesh
          filename="package://virtual_lab/meshes/lidar_link.STL" />
      </geometry>
    </collision>
  </link>
  <joint
    name="lidar_joint"
    type="fixed">
    <origin
      xyz="0.63307 -1.3458 0.93783"
      rpy="1.5708 0 0" />
    <parent
      link="base_link" />
    <child
      link="lidar_link" />
    <axis
      xyz="0 0 0" />
  </joint>
  <link
    name="camera_link">
    <inertial>
      <origin
        xyz="1.1396E-05 -0.00013598 0.011556"
        rpy="0 0 0" />
      <mass
        value="0.10791" />
      <inertia
        ixx="7.7102E-06"
        ixy="-2.5269E-10"
        ixz="-1.7934E-08"
        iyy="7.0257E-05"
        iyz="4.9224E-08"
        izz="7.1255E-05" />
    </inertial>
    <visual>
      <origin
        xyz="0 0 0"
        rpy="0 0 0" />
      <geometry>
        <mesh
          filename="package://virtual_lab/meshes/camera_link.STL" />
      </geometry>
      <material
        name="">
        <color
          rgba="0.86667 0.9098 1 1" />
      </material>
    </visual>
    <collision>
      <origin
        xyz="0 0 0"
        rpy="0 0 0" />
      <geometry>
        <mesh
          filename="package://virtual_lab/meshes/camera_link.STL" />
      </geometry>
    </collision>
  </link>
  <joint
    name="camera_joint"
    type="fixed">
    <origin
      xyz="0.63286 -1.3938 0.89301"
      rpy="1.1384 0 0" />
    <parent
      link="base_link" />
    <child
      link="camera_link" />
    <axis
      xyz="0 0 0" />
  </joint>
</robot>
